Workbook

Sheet Intake
B1: Form 1040 — Individual Income Tax Return
B2: Tax Year 2025 — Comprehensive Intake Worksheet
B3: Blue cells = Client input | Yellow highlight = Required fields
B5: SECTION 1: FILING INFORMATION
B6: Filing Status | D6: 1=Single, 2=MFJ, 3=MFS, 4=HOH, 5=QSS
B7: Digital Assets Question (Y/N) | D7: Did you receive/sell/exchange digital assets?
B8: Standard Deduction or Itemize? | D8: S=Standard, I=Itemize
B9: Are you a dependent of another taxpayer? | D9: Y/N
B10: Presidential Election Campaign Fund? | D10: Y/N
B12: SECTION 2: TAXPAYER INFORMATION
B13: Primary Taxpayer | D13: Spouse (if MFJ/MFS)
B14: First Name | D14: First Name
B15: Middle Initial | D15: Middle Initial
B16: Last Name | D16: Last Name
B17: Social Security Number | D17: Social Security Number
B18: Date of Birth | D18: Date of Birth
B19: Occupation | D19: Occupation
B20: Phone Number | D20: Phone Number
B21: Email Address | D21: Email Address
B22: Legally Blind? (Y/N) | D22: Legally Blind? (Y/N)
B23: Age 65 or Older? (Y/N) | D23: Age 65 or Older? (Y/N)
B24: US Citizen? (Y/N) | D24: US Citizen? (Y/N)
B25: Resident Alien? (Y/N) | D25: Resident Alien? (Y/N)
B27: SECTION 3: MAILING ADDRESS
B28: Street Address
B29: Apartment Number
B30: City
B31: State
B32: ZIP Code
B33: Foreign Country Name
B34: Foreign Province/State
B35: Foreign Postal Code
B37: SECTION 4: DEPENDENTS
B38: First Name | C38: Last Name | D38: SSN | E38: Relationship | F38: Date of Birth | G38: Months Lived w/ You | H38: Child Tax Credit (Y/N) | I38: Other Dependent Credit (Y/N)
B50: SECTION 5: INCOME — WAGES (W-2)
B51: Employer Name | C51: EIN | D51: Wages (Box 1) | E51: Federal Tax Withheld (Box 2) | F51: SS Wages (Box 3) | G51: SS Tax (Box 4) | H51: Medicare Wages (Box 5) | I51: Medicare Tax (Box 6)
B57: Total Wages | D57: =SUM(D52:D56) | E57: =SUM(E52:E56)
B59: SECTION 6: INTEREST INCOME (1099-INT)
B60: Payer Name | C60: EIN | D60: Interest (Box 1) | E60: Tax-Exempt Interest | F60: Federal Tax Withheld | G60: Foreign Tax Paid
B69: Total Taxable Interest | D69: =SUM(D61:D68)
...

Sheet Dashboard
B1: TAX RETURN SUMMARY DASHBOARD
B2: Tax Year 2025 — All amounts auto-calculated
B4: TAXPAYER INFORMATION
B5: Name | C5: =Intake!C13&" "&Intake!C15
B6: Filing Status | C6: =IF(Intake!C6=1,"Single",IF(Intake!C6=2,"Married Filing Jointly",IF(Intake!C6=3,"Married Filing Separately",IF(Intake!C6=4,"Head of Household","Qualifying Surviving Spouse"))))
B8: INCOME SUMMARY
B9: Wages & Salaries | C9: ='Form 1040'!D8
B10: Taxable Interest | C10: ='Form 1040'!D10
B11: Ordinary Dividends | C11: ='Form 1040'!D12
B12: Capital Gains/(Losses) | C12: ='Form 1040'!D19
B13: Business Income (Sch C) | C13: ='Schedule C'!D45
B14: Rental Income (Sch E) | C14: ='Schedule E'!D50
B15: Other Income (Sch 1) | C15: ='Form 1040'!D20
B16: TOTAL INCOME | C16: ='Form 1040'!D21
B18: TAX COMPUTATION SUMMARY
B19: Adjusted Gross Income | C19: ='Form 1040'!D25
B20: Deductions | C20: ='Form 1040'!D30
B21: Taxable Income | C21: ='Form 1040'!D31
B22: Income Tax | C22: ='Form 1040'!D34
B23: Self-Employment Tax | C23: ='Schedule SE'!D18
B24: Total Tax | C24: ='Form 1040'!D40
B25: Total Payments | C25: ='Form 1040'!D53
B26: REFUND | C26: ='Form 1040'!D56
B27: AMOUNT OWED | C27: ='Form 1040'!D58
B29: FOREIGN REPORTING REQUIREMENTS
B30: FBAR Required? | C30: =IF(Intake!F247>10000,"YES","NO")
B31: Form 8938 (FATCA) Required? | C31: ='Form 8938'!D10
B32: Form 3520 Required? | C32: =IF(OR('Form 3520'!D5>100000,'Form 3520'!D6>19570),"YES","NO")
B33: Form 8621 (PFIC) Required? | C33: =IF(COUNTA(Intake!B274:B278)>0,"YES","NO")

Sheet Tax Tables
B1: 2025 Federal Tax Tables & Key Thresholds
B3: ORDINARY INCOME TAX BRACKETS — TAX YEAR 2025
B4: Rate | C4: Single | D4: MFJ | E4: MFS | F4: HOH
B5: 10% | C5: $0 – $11,925 | D5: $0 – $23,850 | E5: $0 – $11,925 | F5: $0 – $17,000
B6: 12% | C6: $11,925 – $48,475 | D6: $23,850 – $96,950 | E6: $11,925 – $48,475 | F6: $17,000 – $64,850
B7: 22% | C7: $48,475 – $103,350 | D7: $96,950 – $206,700 | E7: $48,475 – $103,350 | F7: $64,850 – $103,350
B8: 24% | C8: $103,350 – $197,300 | D8: $206,700 – $394,600 | E8: $103,350 – $197,300 | F8: $103,350 – $197,300
B9: 32% | C9: $197,300 – $250,525 | D9: $394,600 – $501,050 | E9: $197,300 – $250,525 | F9: $197,300 – $250,500
B10: 35% | C10: $250,525 – $626,350 | D10: $501,050 – $751,600 | E10: $250,525 – $626,350 | F10: $250,500 – $626,350
B11: 37% | C11: Over $626,350 | D11: Over $751,600 | E11: Over $626,350 | F11: Over $626,350
B13: BRACKET THRESHOLDS (Numeric — Used by Formulas)
B14: Rate | C14: Single Lower | D14: Single Upper | E14: MFJ Lower | F14: MFJ Upper | G14: HOH Lower
B15: 0.1 | C15: 0 | D15: 11925 | E15: 0 | F15: 23850 | G15: 0
B16: 0.12 | C16: 11925 | D16: 48475 | E16: 23850 | F16: 96950 | G16: 17000
B17: 0.22 | C17: 48475 | D17: 103350 | E17: 96950 | F17: 206700 | G17: 64850
B18: 0.24 | C18: 103350 | D18: 197300 | E18: 206700 | F18: 394600 | G18: 103350
B19: 0.32 | C19: 197300 | D19: 250525 | E19: 394600 | F19: 501050 | G19: 197300
B20: 0.35 | C20: 250525 | D20: 626350 | E20: 501050 | F20: 751600 | G20: 250500
B21: 0.37 | C21: 626350 | D21: 9999999 | E21: 751600 | F21: 9999999 | G21: 626350
B23: STANDARD DEDUCTIONS
B24: Single | C24: 15750
B25: Married Filing Jointly | C25: 31500
B26: Married Filing Separately | C26: 15750
B27: Head of Household | C27: 23625
B28: Qualifying Surviving Spouse | C28: 31500
B29: Additional — Age 65+ or Blind (Single/HOH) | C29: 2000
B30: Additional — Age 65+ or Blind (MFJ/MFS, per person) | C30: 1600
B32: LONG-TERM CAPITAL GAINS RATES
B33: Rate | C33: Single | D33: MFJ | E33: HOH
B34: 0% | C34: $0 – $48,350 | D34: $0 – $96,700 | E34: $0 – $64,750
B35: 15% | C35: $48,350 – $533,400 | D35: $96,700 – $600,050 | E35: $64,750 – $566,700
B36: 20% | C36: Over $533,400 | D36: Over $600,050 | E36: Over $566,700
B38: KEY THRESHOLDS & LIMITS
B39: Social Security Wage Base | C39: 176100
B40: SE Tax Rate — Social Security (12.4%) | C40: 0.124
B41: SE Tax Rate — Medicare (2.9%) | C41: 0.029
B42: Additional Medicare Tax Threshold (Single) | C42: 200000
B43: Additional Medicare Tax Threshold (MFJ) | C43: 250000
B44: Additional Medicare Tax Rate | C44: 0.009
B45: Net Investment Income Tax Threshold (Single) | C45: 200000
...

Sheet Form 1040
B1: Form 1040 — U.S. Individual Income Tax Return (2025)
B2: All amounts pull from Intake and Schedule tabs via formulas
B4: INCOME
B5: 1a | C5: Wages, salaries, tips (W-2, Box 1) | D5: =Intake!D57
B6: 1b | C6: Household employee income (not on W-2) | D6: =Intake!C181
B7: 1c | C7: Tip income not on W-2 | D7: =Intake!C181
B8: 1z | C8: Total from lines 1a through 1c | D8: =D5+D6+D7
B9: 2a | C9: Tax-exempt interest | D9: =Intake!E69
B10: 2b | C10: Taxable interest | D10: =Intake!D69
B11: 3a | C11: Qualified dividends | D11: =Intake!D83
B12: 3b | C12: Ordinary dividends | D12: =Intake!C82
B13: 4a | C13: IRA distributions — Gross | D13: =Intake!C169
B14: 4b | C14: IRA distributions — Taxable | D14: =Intake!C170
B15: 5a | C15: Pensions and annuities — Gross | D15: =Intake!C171
B16: 5b | C16: Pensions and annuities — Taxable | D16: =Intake!C172
B17: 6a | C17: Social Security benefits — Gross | D17: =Intake!C173
B18: 6b | C18: Social Security benefits — Taxable | D18: =Intake!C174
B19: 7 | C19: Capital gain or (loss) — Schedule D | D19: ='Schedule D'!D50
B20: 8 | C20: Other income from Schedule 1, line 10 | D20: ='Schedule 1'!D30
B21: 9 | C21: Total income (add 1z, 2b, 3b, 4b, 5b, 6b, 7, 8) | D21: =D8+D10+D12+D14+D16+D18+D19+D20
B23: ADJUSTED GROSS INCOME
B24: 10 | C24: Adjustments from Schedule 1, line 26 | D24: ='Schedule 1'!D60
B25: 11 | C25: Adjusted gross income (line 9 minus line 10) | D25: =D21-D24
B27: DEDUCTIONS & TAXABLE INCOME
B28: 12 | C28: Standard deduction or itemized deductions | D28: ='Deduction Calc'!D10
B29: 13 | C29: Qualified business income deduction (Sec 199A) | D29: =Intake!C184
B30: 14 | C30: Total deductions (line 12 + line 13) | D30: =D28+D29
B31: 15 | C31: Taxable income (line 11 minus line 14, not less than 0) | D31: =MAX(0,D25-D30)
B33: TAX COMPUTATION
B34: 16 | C34: Tax (from Tax Computation worksheet) | D34: ='Tax Computation'!D30
B35: 17 | C35: Amount from Schedule 2, line 21 (additional taxes) | D35: ='Schedule 2'!D25
B36: 18 | C36: Total tax before credits (line 16 + 17) | D36: =D34+D35
B37: 19 | C37: Nonrefundable credits from Schedule 3, line 8 | D37: ='Schedule 3'!D15
B38: 20 | C38: Subtract line 19 from 18 (not less than 0) | D38: =MAX(0,D36-D37)
B39: 21 | C39: Other taxes from Schedule 2, line 21 | D39: ='Schedule 2'!D25
B40: 22 | C40: Total tax (line 20 + 21) | D40: =D38+D39
B42: PAYMENTS
B43: 23 | C43: Federal income tax withheld | D43: =Intake!C233
B44: 24 | C44: Estimated tax payments + amount applied from prior year | D44: =Intake!C234+Intake!C235+Intake!C236+Intake!C237+Intake!C238
B45: 25 | C45: Earned income credit | D45: =Intake!C229
...

Sheet Deduction Calc
B1: Deduction Determination Worksheet
B3: STANDARD DEDUCTION CALCULATION
B4: 1 | C4: Filing Status | D4: =Intake!C6
B5: 2 | C5: Base standard deduction for filing status | D5: =IF(D4=1,15750,IF(D4=2,31500,IF(D4=3,15750,IF(D4=4,23625,IF(D4=5,31500,0)))))
B6: 3 | C6: Additional for age 65+ (primary) | D6: =IF(Intake!C17="Y",IF(OR(D4=1,D4=4),2000,1600),0)
B7: 4 | C7: Additional for age 65+ (spouse, if MFJ) | D7: =IF(AND(D4=2,Intake!E17="Y"),1600,0)
B8: 5 | C8: Additional for blindness (primary) | D8: =IF(Intake!C16="Y",IF(OR(D4=1,D4=4),2000,1600),0)
B9: 6 | C9: Total standard deduction | D9: =SUM(D5:D8)
B11: ITEMIZED DEDUCTIONS TOTAL
B12: 7 | C12: Total itemized deductions (from Schedule A) | D12: ='Schedule A'!D30
B14: DEDUCTION USED ON RETURN
B15: 8 | C15: Greater of standard or itemized (or per taxpayer choice) | D15: =IF(Intake!C8="I",D12,IF(Intake!C8="S",D9,MAX(D9,D12)))

Sheet Tax Computation
B1: Tax Computation Worksheet — 2025
B3: Calculates ordinary income tax using progressive bracket rates
B5: INPUTS
C6: Filing Status | D6: =Intake!C6
C7: Taxable Income (from Form 1040, Line 15) | D7: ='Form 1040'!D31
B9: PROGRESSIVE TAX CALCULATION
B10: # | C10: Bracket Description | D10: Tax in Bracket
B11: 1 | C11: 10% bracket | D11: =IF(D$7>0,IF(OR(D$6=1,D$6=3),0.1*MAX(0,MIN(D$7,11925)-0),IF(D$6=2,0.1*MAX(0,MIN(D$7,23850)-0),IF(D$6=4,0.1*MAX(0,MIN(D$7,17000)-0),0.1*MAX(0,MIN(D$7,11925)-0)))),0)
B12: 2 | C12: 12% bracket | D12: =IF(D$7>0,IF(OR(D$6=1,D$6=3),0.12*MAX(0,MIN(D$7,48475)-11925),IF(D$6=2,0.12*MAX(0,MIN(D$7,96950)-23850),IF(D$6=4,0.12*MAX(0,MIN(D$7,64850)-17000),0.12*MAX(0,MIN(D$7,48475)-11925)))),0)
B13: 3 | C13: 22% bracket | D13: =IF(D$7>0,IF(OR(D$6=1,D$6=3),0.22*MAX(0,MIN(D$7,103350)-48475),IF(D$6=2,0.22*MAX(0,MIN(D$7,206700)-96950),IF(D$6=4,0.22*MAX(0,MIN(D$7,103350)-64850),0.22*MAX(0,MIN(D$7,103350)-48475)))),0)
B14: 4 | C14: 24% bracket | D14: =IF(D$7>0,IF(OR(D$6=1,D$6=3),0.24*MAX(0,MIN(D$7,197300)-103350),IF(D$6=2,0.24*MAX(0,MIN(D$7,394600)-206700),IF(D$6=4,0.24*MAX(0,MIN(D$7,197300)-103350),0.24*MAX(0,MIN(D$7,197300)-103350)))),0)
B15: 5 | C15: 32% bracket | D15: =IF(D$7>0,IF(OR(D$6=1,D$6=3),0.32*MAX(0,MIN(D$7,250525)-197300),IF(D$6=2,0.32*MAX(0,MIN(D$7,501050)-394600),IF(D$6=4,0.32*MAX(0,MIN(D$7,250500)-197300),0.32*MAX(0,MIN(D$7,250525)-197300)))),0)
B16: 6 | C16: 35% bracket | D16: =IF(D$7>0,IF(OR(D$6=1,D$6=3),0.35*MAX(0,MIN(D$7,626350)-250525),IF(D$6=2,0.35*MAX(0,MIN(D$7,751600)-501050),IF(D$6=4,0.35*MAX(0,MIN(D$7,626350)-250500),0.35*MAX(0,MIN(D$7,626350)-250525)))),0)
B17: 7 | C17: 37% bracket | D17: =IF(D$7>0,IF(OR(D$6=1,D$6=3),0.37*MAX(0,MIN(D$7,99999999)-626350),IF(D$6=2,0.37*MAX(0,MIN(D$7,99999999)-751600),IF(D$6=4,0.37*MAX(0,MIN(D$7,99999999)-626350),0.37*MAX(0,MIN(D$7,99999999)-626350)))),0)
C19: Total Ordinary Income Tax | D19: =SUM(D11:D17)
B21: QUALIFIED DIVIDENDS & LTCG TAX (SIMPLIFIED)
C22: Qualified dividends | D22: ='Form 1040'!D11
C23: Net LTCG from Schedule D | D23: ='Schedule D'!D48
C24: Total preferential rate income | D24: =D22+MAX(0,D23)
C25: Note: Full QDCG worksheet computation recommended for complex returns
C30: TAX (Line 16 of Form 1040) | D30: =D19

Sheet Schedule 1
B1: Schedule 1 — Additional Income and Adjustments to Income
B3: PART I — ADDITIONAL INCOME
B4: 1 | C4: Taxable refunds of state/local taxes | D4: =Intake!C167
B5: 2a | C5: Alimony received (pre-2019 divorce) | D5: =Intake!C168
B6: 3 | C6: Business income or (loss) — Schedule C | D6: ='Schedule C'!D45
B7: 4 | C7: Other gains or (losses) — Form 4797
B8: 5 | C8: Rental real estate, royalties, partnerships, S corps — Schedule E | D8: ='Schedule E'!D50
B9: 6 | C9: Farm income or (loss) — Schedule F | D9: =Intake!C179
B10: 7 | C10: Unemployment compensation | D10: =Intake!C175
B11: 8a | C11: Net operating loss
B12: 8b | C12: Gambling income | D12: =Intake!C176
B13: 8c | C13: Cancellation of debt
B14: 8d | C14: Foreign earned income exclusion (Form 2555)
B15: 8z | C15: Other income (list type and amount) | D15: =Intake!C178
B16: 9 | C16: Total other income (sum 8a through 8z) | D16: =SUM(D11:D15)
B17: 10 | C17: Total additional income (add lines 1 through 7 plus 9) | D17: =D4+D5+D6+D7+D8+D9+D10+D16
C28: Carried to Form 1040, Line 8
B30: 10 | C30: Total additional income → Form 1040 Line 8 | D30: =D17
B32: PART II — ADJUSTMENTS TO INCOME
B33: 11 | C33: Educator expenses | D33: =Intake!C184
B34: 12 | C34: Business expenses (reservists, etc.) | D34: =Intake!C185
B35: 13 | C35: HSA deduction | D35: =Intake!C186
B36: 14 | C36: Moving expenses (military) | D36: =Intake!C187
B37: 15 | C37: Deductible part of self-employment tax | D37: ='Schedule SE'!D20
B38: 16 | C38: Self-employed SEP/SIMPLE/qualified plans | D38: =Intake!C189
B39: 17 | C39: Self-employed health insurance | D39: =Intake!C190
B40: 18 | C40: Penalty on early withdrawal of savings | D40: =Intake!C191
B41: 19 | C41: IRA deduction | D41: =Intake!C192
B42: 20 | C42: Student loan interest deduction | D42: =Intake!C193
B43: 22 | C43: Other adjustments | D43: =Intake!C197
B44: 25 | C44: Total Part II adjustments | D44: =SUM(D33:D43)
B45: 26 | C45: Total adjustments → Form 1040 Line 10 | D45: =D44
B60: 26 | C60: Total adjustments to income → Form 1040 Line 10 | D60: =D45

Sheet Schedule 2
B1: Schedule 2 — Additional Taxes
B3: PART I — TAX
B4: 1 | C4: AMT (Form 6251)
B5: 2 | C5: Excess premium tax credit repayment
B6: 3 | C6: Total (add lines 1 and 2) → Form 1040 Line 17 | D6: =D4+D5
B8: PART II — OTHER TAXES
B9: 6 | C9: Self-employment tax (Schedule SE) | D9: ='Schedule SE'!D18
B10: 8 | C10: Additional Medicare Tax (Form 8959)
B11: 9 | C11: Net investment income tax (Form 8960)
B12: 10 | C12: Uncollected SS/Medicare on tips
B13: 11 | C13: Additional tax on IRAs/retirement (10%)
B14: 12 | C14: Additional tax on HSA distributions
B15: 17 | C15: Total additional taxes (sum) | D15: =SUM(D9:D14)
B16: 21 | C16: Total Other Taxes → Form 1040 Line 21 | D16: =D15
B25: 21 | C25: Schedule 2 Total → Form 1040 | D25: =D16

Sheet Schedule 3
B1: Schedule 3 — Additional Credits and Payments
B3: PART I — NONREFUNDABLE CREDITS
B4: 1 | C4: Foreign tax credit (Form 1116) | D4: =Intake!C217
B5: 2 | C5: Child and dependent care credit (Form 2441) | D5: =Intake!C218
B6: 3 | C6: Education credits (Form 8863) | D6: =Intake!C219+Intake!C220
B7: 4 | C7: Retirement savings credit (Form 8880) | D7: =Intake!C221
B8: 5a | C8: Residential energy credit | D8: =Intake!C223
B9: 5b | C9: EV credit | D9: =Intake!C224
B10: 7 | C10: Other nonrefundable credits | D10: =Intake!C225
B11: 8 | C11: Total nonrefundable credits → Form 1040 Line 19 | D11: =SUM(D4:D10)
B15: 8 | C15: Total nonrefundable credits → Form 1040 Line 19 | D15: =D11
B17: PART II — OTHER PAYMENTS AND REFUNDABLE CREDITS
B18: 9 | C18: Net premium tax credit (Form 8962) | D18: =Intake!C228
B19: 10 | C19: Amount paid with extension | D19: =Intake!C239
B20: 11 | C20: Excess SS tax withheld | D20: =Intake!C240
B21: 13 | C21: Other refundable credits | D21: =Intake!C230
B22: 15 | C22: Total other payments → Form 1040 | D22: =SUM(D18:D21)
B25: 15 | C25: Total other payments/refundable credits → Form 1040 | D25: =D22

Sheet Schedule A
B1: Schedule A — Itemized Deductions
B3: MEDICAL AND DENTAL EXPENSES
B4: 1 | C4: Medical and dental expenses | D4: =Intake!C200
B5: 2 | C5: AGI | D5: ='Form 1040'!D25
B6: 3 | C6: 7.5% of AGI threshold | D6: =D5*0.075
B7: 4 | C7: Deductible medical expenses (excess over 7.5% AGI) | D7: =MAX(0,D4-D6)
B9: TAXES YOU PAID
B10: 5a | C10: State/local income taxes OR sales taxes | D10: =MAX(Intake!C201,Intake!C202)
B11: 5b | C11: Real estate taxes | D11: =Intake!C203
B12: 5c | C12: Personal property taxes | D12: =Intake!C204
B13: 5d | C13: Total SALT (capped at $10,000) | D13: =MIN(10000,D10+D11+D12)
B15: INTEREST YOU PAID
B16: 8a | C16: Home mortgage interest (Form 1098) | D16: =Intake!C206
B17: 8d | C17: Mortgage insurance premiums | D17: =Intake!C207
B18: 9 | C18: Investment interest expense | D18: =Intake!C208
B19: 10 | C19: Total interest deduction | D19: =D16+D17+D18
B21: GIFTS TO CHARITY
B22: 11 | C22: Cash contributions | D22: =Intake!C209
B23: 12 | C23: Noncash contributions | D23: =Intake!C210
B24: 13 | C24: Carryover from prior year | D24: =Intake!C211
B25: 14 | C25: Total charitable deduction | D25: =D22+D23+D24
B27: OTHER DEDUCTIONS
B28: 15 | C28: Casualty/theft losses (federally declared disaster) | D28: =Intake!C212
B29: 16 | C29: Gambling losses (limited to winnings) | D29: =Intake!C213
B30: 18 | C30: TOTAL ITEMIZED DEDUCTIONS | D30: =D7+D13+D19+D25+D28+D29+D30

Sheet Schedule B
B1: Schedule B — Interest and Ordinary Dividends
B3: PART I — INTEREST (pulls from Intake Section 6)
C4: See Intake tab for detailed 1099-INT entries
B5: 1 | C5: Total interest income | D5: =Intake!D69
B6: 4 | C6: Taxable interest → Form 1040 Line 2b | D6: =Intake!D69
B8: PART II — ORDINARY DIVIDENDS (pulls from Intake Section 7)
B9: 5 | C9: Total ordinary dividends | D9: =Intake!C82
B10: 6 | C10: Ordinary dividends → Form 1040 Line 3b | D10: =Intake!C82
B12: PART III — FOREIGN ACCOUNTS AND TRUSTS
B13: 7a | C13: Do you have foreign accounts or foreign trusts? (Y/N) | D13: =Intake!C245
B14: 7b | C14: Country where accounts are located
B15: 8 | C15: Are you required to file FinCEN Form 114 (FBAR)? (Y/N) | D15: =IF(Intake!F247>10000,"YES","NO")

Sheet Schedule C
B1: Schedule C — Profit or Loss from Business
B3: BUSINESS INFORMATION
B4: A | C4: Principal business or profession | D4: =Intake!C113
B5: B | C5: Business name | D5: =Intake!C111
B6: C | C6: Business EIN | D6: =Intake!C112
B7: D | C7: Business address | D7: =Intake!C114
B8: F | C8: Accounting method | D8: =Intake!C115
B10: INCOME
B11: 1 | C11: Gross receipts or sales | D11: =Intake!C116
B12: 2 | C12: Returns and allowances | D12: =Intake!C117
B13: 4 | C13: Cost of goods sold | D13: =Intake!C118
B14: 5 | C14: Gross profit (Line 1 - 2 - 4) | D14: =D11-D12-D13
B16: EXPENSES
B17: 8 | C17: Advertising | D17: =Intake!C119
B18: 9 | C18: Car and truck expenses | D18: =Intake!C120
B19: 10 | C19: Commissions and fees | D19: =Intake!C121
B20: 11 | C20: Contract labor | D20: =Intake!C122
B21: 13 | C21: Depreciation (Form 4562) | D21: =Intake!C123
B22: 14 | C22: Employee benefit programs | D22: =Intake!C124
B23: 15 | C23: Insurance (other than health) | D23: =Intake!C125
B24: 16a | C24: Mortgage interest | D24: =Intake!C126
B25: 16b | C25: Other interest | D25: =Intake!C127
B26: 17 | C26: Legal and professional services | D26: =Intake!C128
B27: 18 | C27: Office expense | D27: =Intake!C129
B28: 20a | C28: Rent — vehicles/machinery | D28: =Intake!C130
... B36: 26 | C36: Wages | D36: =Intake!C138
B37: 27a | C37: Other expenses | D37: =Intake!C140
B38: 28 | C38: Total expenses | D38: =SUM(D17:D37)
B39: 29 | C39: Tentative profit (loss) | D39: =D14-D38
B40: 30 | C40: Business use of home (Form 8829) | D40: =Intake!C141
B45: 31 | C45: NET PROFIT (LOSS) → Schedule 1 Line 3 | D45: =D39-D40

Sheet Schedule D
B1: Schedule D — Capital Gains and Losses
B3: PART I — SHORT-TERM CAPITAL GAINS AND LOSSES
B4: 7 | C4: Net short-term gain (loss) from Form 8949 | D4: ='Form 8949'!D30
B5: 8 | C5: Short-term gain from K-1s and other forms
B6: 9 | C6: Short-term capital loss carryover
B7: 10 | C7: Net short-term capital gain (loss) | D7: =D4+D5+D6
B9: PART II — LONG-TERM CAPITAL GAINS AND LOSSES
B10: 15 | C10: Net long-term gain (loss) from Form 8949 | D10: ='Form 8949'!D60
B11: 16 | C11: Long-term gain from K-1s and Form 1099-DIV cap gain dist
B12: 17 | C12: Long-term capital loss carryover
B13: 18 | C13: Net long-term capital gain (loss) | D13: =D10+D11+D12
B15: PART III — SUMMARY
B16: 19 | C16: Combine lines 10 and 18 | D16: =D7+D13
B17: 20 | C17: Capital loss limitation ($3,000 max or $1,500 MFS) | D17: =IF(D16<0,MAX(D16,-3000),D16)
C48: Net LTCG (for Tax Computation) | D48: =MAX(0,D13)
B50: 21 | C50: NET CAPITAL GAIN (LOSS) → Form 1040 Line 7 | D50: =D17

Sheet Form 8949
B1: Form 8949 — Sales and Other Dispositions of Capital Assets
B3: PART I — SHORT-TERM (held one year or less)
B4: Description | C4: Date Acquired | D4: Date Sold | E4: Proceeds | F4: Cost Basis | G4: Gain/(Loss)
G5: =IF(OR(E5="",F5=""),"",E5-F5)
G6: =IF(OR(E6="",F6=""),"",E6-F6)
G7: =IF(OR(E7="",F7=""),"",E7-F7)
G8: =IF(OR(E8="",F8=""),"",E8-F8)
G9: =IF(OR(E9="",F9=""),"",E9-F9)
G10: =IF(OR(E10="",F10=""),"",E10-F10)
G11: =IF(OR(E11="",F11=""),"",E11-F11)
G12: =IF(OR(E12="",F12=""),"",E12-F12)
G13: =IF(OR(E13="",F13=""),"",E13-F13)
G14: =IF(OR(E14="",F14=""),"",E14-F14)
G15: =IF(OR(E15="",F15=""),"",E15-F15)
G16: =IF(OR(E16="",F16=""),"",E16-F16)
... G19: =IF(OR(E19="",F19=""),"",E19-F19)
B29: Total Short-Term | E29: =SUM(E5:E19) | F29: =SUM(F5:F19)
B30: Net Short-Term Gain/(Loss) → Schedule D | D30: =SUM(G5:G19)
B32: PART II — LONG-TERM (held more than one year)
B33: Description | C33: Date Acquired | D33: Date Sold | E33: Proceeds | F33: Cost Basis | G33: Gain/(Loss)
G34: =IF(OR(E34="",F34=""),"",E34-F34)
G35: =IF(OR(E35="",F35=""),"",E35-F35)
G36: =IF(OR(E36="",F36=""),"",E36-F36)
G37: =IF(OR(E37="",F37=""),"",E37-F37)
G38: =IF(OR(E38="",F38=""),"",E38-F38)
G39: =IF(OR(E39="",F39=""),"",E39-F39)
G40: =IF(OR(E40="",F40=""),"",E40-F40)
G41: =IF(OR(E41="",F41=""),"",E41-F41)
G42: =IF(OR(E42="",F42=""),"",E42-F42)
G43: =IF(OR(E43="",F43=""),"",E43-F43)
G44: =IF(OR(E44="",F44=""),"",E44-F44)
G45: =IF(OR(E45="",F45=""),"",E45-F45)
... G48: =IF(OR(E48="",F48=""),"",E48-F48)
B59: Total Long-Term | E59: =SUM(E34:E48) | F59: =SUM(F34:F48)
B60: Net Long-Term Gain/(Loss) → Schedule D | D60: =SUM(G34:G48)

Sheet Schedule E
B1: Schedule E — Supplemental Income and Loss
B3: PART I — RENTAL REAL ESTATE AND ROYALTIES
C4: Item | D4: Property 1 | E4: Property 2 | F4: Property 3
B5: 3 | C5: Rents received | D5: =Intake!C149 | E5: =Intake!D149 | F5: =Intake!E149
B6: 5 | C6: Advertising | D6: =Intake!C150 | E6: =Intake!D150 | F6: =Intake!E150
B7: 6 | C7: Auto and travel | D7: =Intake!C151 | E7: =Intake!D151 | F7: =Intake!E151
B8: 7 | C8: Cleaning and maintenance | D8: =Intake!C152 | E8: =Intake!D152 | F8: =Intake!E152
B9: 8 | C9: Commissions | D9: =Intake!C153 | E9: =Intake!D153 | F9: =Intake!E153
B10: 9 | C10: Insurance | D10: =Intake!C154 | E10: =Intake!D154 | F10: =Intake!E154
B11: 10 | C11: Legal and professional | D11: =Intake!C155 | E11: =Intake!D155 | F11: =Intake!E155
B12: 11 | C12: Management fees | D12: =Intake!C156 | E12: =Intake!D156 | F12: =Intake!E156
B13: 12 | C13: Mortgage interest | D13: =Intake!C157 | E13: =Intake!D157 | F13: =Intake!E157
B14: 13 | C14: Other interest | D14: =Intake!C158 | E14: =Intake!D158 | F14: =Intake!E158
B15: 14 | C15: Repairs | D15: =Intake!C159 | E15: =Intake!D159 | F15: =Intake!E159
B16: 15 | C16: Supplies | D16: =Intake!C160 | E16: =Intake!D160 | F16: =Intake!E160
... B20: 19 | C20: Other | D20: =Intake!C164 | E20: =Intake!D164 | F20: =Intake!E164
B22: 20 | C22: Total expenses | D22: =SUM(D6:D20) | E22: =SUM(E6:E20) | F22: =SUM(F6:F20)
B23: 21 | C23: Net rental income (loss) per property | D23: =D5-D22 | E23: =E5-E22 | F23: =F5-F22
B25: PART II — INCOME FROM PARTNERSHIPS AND S CORPORATIONS
C26: See Intake Section 19 for K-1 details
B27: 32 | C27: Total K-1 ordinary income | D27: =SUM(Intake!E282:E286)
B28: 33 | C28: Total K-1 rental income | D28: =SUM(Intake!F282:F286)
B50: 41 | C50: TOTAL SCH E INCOME (LOSS) → Schedule 1 | D50: =D23+E23+F23+D27+D28

Sheet Schedule SE
B1: Schedule SE — Self-Employment Tax
B3: SELF-EMPLOYMENT TAX CALCULATION
B4: 1 | C4: Net farm profit (loss) — Schedule F
B5: 2 | C5: Net profit (loss) from Schedule C | D5: ='Schedule C'!D45
B6: 3 | C6: Combined (lines 1 + 2) | D6: =D4+D5
B7: 4 | C7: 92.35% of line 3 (net earnings subject to SE tax) | D7: =D6*0.9235
B8: 5 | C8: Social Security wage base limit ($176,100) | D8: 176100
B9: 6 | C9: W-2 Social Security wages (reduces SE base) | D9: =Intake!D57
B10: 7 | C10: Remaining SS wage room | D10: =MAX(0,D8-D9)
B11: 8 | C11: Social Security portion (12.4% on lesser of net earnings or room) | D11: =MIN(D7,D10)*0.124
B12: 9 | C12: Medicare portion (2.9% on all net earnings) | D12: =D7*0.029
B13: 10 | C13: TOTAL SELF-EMPLOYMENT TAX → Schedule 2 | D13: =D11+D12
C18: Self-Employment Tax (output row) | D18: =D13
B20: 11 | C20: Deductible part of SE tax (50%) → Schedule 1 | D20: =D13*0.5

Sheet Form 8938
B1: Form 8938 — Statement of Specified Foreign Financial Assets
B3: FILING THRESHOLD DETERMINATION
C4: Filing Status | D4: =Intake!C6
C5: Taxpayer lives abroad? (Y/N)
C6: Maximum aggregate value during year | D6: =Intake!F247
C7: Year-end aggregate value | D7: =SUM(Intake!G250:G259)
C8: Filing threshold (year-end) | D8: =IF(D5="Y",IF(OR(D4=1,D4=3),200000,IF(D4=2,400000,200000)),IF(OR(D4=1,D4=3),50000,IF(D4=2,100000,50000)))
C9: Filing threshold (any time during year) | D9: =IF(D5="Y",IF(OR(D4=1,D4=3),300000,IF(D4=2,600000,300000)),IF(OR(D4=1,D4=3),75000,IF(D4=2,150000,75000)))
C10: FORM 8938 REQUIRED? | D10: =IF(OR(D7>D8,D6>D9),"YES - FILING REQUIRED","NO")
B12: PART I — FOREIGN DEPOSIT AND CUSTODIAL ACCOUNTS
C13: (Pulls from Intake Section 16)
B14: Account Type | C14: Institution | D14: Country | E14: Max Value | F14: Year-End Value
B15: =Intake!B250 | C15: =Intake!C250 | D15: =Intake!D250 | E15: =Intake!F250 | F15: =Intake!G250
B16: =Intake!B251 | C16: =Intake!C251 | D16: =Intake!D251 | E16: =Intake!F251 | F16: =Intake!G251
B17: =Intake!B252 | C17: =Intake!C252 | D17: =Intake!D252 | E17: =Intake!F252 | F17: =Intake!G252
B18: =Intake!B253 | C18: =Intake!C253 | D18: =Intake!D253 | E18: =Intake!F253 | F18: =Intake!G253
B19: =Intake!B254 | C19: =Intake!C254 | D19: =Intake!D254 | E19: =Intake!F254 | F19: =Intake!G254
B20: =Intake!B255 | C20: =Intake!C255 | D20: =Intake!D255 | E20: =Intake!F255 | F20: =Intake!G255
B21: =Intake!B256 | C21: =Intake!C256 | D21: =Intake!D256 | E21: =Intake!F256 | F21: =Intake!G256
B22: =Intake!B257 | C22: =Intake!C257 | D22: =Intake!D257 | E22: =Intake!F257 | F22: =Intake!G257
B23: =Intake!B258 | C23: =Intake!C258 | D23: =Intake!D258 | E23: =Intake!F258 | F23: =Intake!G258
B24: =Intake!B259 | C24: =Intake!C259 | D24: =Intake!D259 | E24: =Intake!F259 | F24: =Intake!G259
B26: PART IV — SUMMARY OF TAX ITEMS
C27: Total interest from foreign accounts | D27: =SUM(Intake!H250:H259)
C28: Total dividends from foreign accounts
C29: Total gains from foreign accounts

Sheet Form 8621
B1: Form 8621 — Information Return by a Shareholder of a PFIC
B3: PFIC INFORMATION (from Intake Section 18)
B4: PFIC Name | C4: Country | D4: EIN/Ref ID | E4: FMV (Year-End)
B5: =Intake!B274 | C5: =Intake!C274 | D5: =Intake!D274 | E5: =Intake!G274
B6: =Intake!B275 | C6: =Intake!C275 | D6: =Intake!D275 | E6: =Intake!G275
B7: =Intake!B276 | C7: =Intake!C276 | D7: =Intake!D276 | E7: =Intake!G276
B8: =Intake!B277 | C8: =Intake!C277 | D8: =Intake!D277 | E8: =Intake!G277
B9: =Intake!B278 | C9: =Intake!C278 | D9: =Intake!D278 | E9: =Intake!G278
B11: ELECTION AND INCOME DETAILS
C12: Note: Complete one Form 8621 per PFIC. This is a summary worksheet.
B13: PFIC Name | C13: Election Type | D13: Ordinary Income | E13: Net Capital Gain
B14: =Intake!B274 | C14: =Intake!H274
B15: =Intake!B275 | C15: =Intake!H275
B16: =Intake!B276 | C16: =Intake!H276
B17: =Intake!B277 | C17: =Intake!H277
B18: =Intake!B278 | C18: =Intake!H278

Sheet Form 3520
B1: Form 3520 — Annual Return to Report Transactions with Foreign Trusts
B2: and Receipt of Certain Foreign Gifts
B4: PART IV — US PERSONS RECEIVING FOREIGN GIFTS
C5: Total gifts from foreign individuals | D5: =Intake!C263
C6: Total gifts from foreign corporations | D6: =Intake!C264
C7: FORM 3520 REQUIRED FOR GIFTS? | D7: =IF(OR(D5>100000,D6>19570),"YES - FILING REQUIRED","NO")
B9: PART III — US PERSONS WITH FOREIGN TRUSTS
C10: Name of foreign trust | D10: =Intake!C265
C11: Country of trust | D11: =Intake!C266
C12: EIN or Reference ID | D12: =Intake!C267
C13: Distributions received from trust | D13: =Intake!C268
C14: Transfers to trust during year | D14: =Intake!C269
C16: FORM 3520 REQUIRED FOR TRUST? | D16: =IF(OR(D14<>0,D15<>0),"YES - FILING REQUIRED","NO")
